Workbook

Sheet 說明
A1: 租書店試算表 v1
A2: 用途 | B2: #01.3 比較篇的試作：用試算表做 #01 那五個櫃檯動作，看它此時夠不夠用。資料來自 #00.1 種子資料 S 規模（seed 20260905）。
A3: 三張表 | B3: 「書籍」「會員」是名冊，「借閱」是流水帳，一次借還一列。
A4: 怎麼借出 | B4: 到「借閱」最下面新增一列：填會員編號、ISBN、借出日期，歸還日期留空。
A5: 怎麼歸還 | B5: 在「借閱」找到那一列（用篩選：ISBN＝該書、歸還日期＝空白），填上歸還日期。
A6: 可以改的格 | B6: 藍字是手填資料，黑字是公式，綠字是查表帶出來的。公式範圍到第 2000 列。
A7: 會被擋下的 | B7: 會員編號、ISBN 只能從下拉清單選（資料驗證），打錯會拒絕。
A8: 不會被擋下的 | B8: 同一本書借出中再借一次。試算表只會在「書籍」把未歸還筆數標紅，不會阻止你新增那一列。

Sheet 借閱
A1: 會員編號 | B1: ISBN | C1: 借出日期 | D1: 歸還日期 | E1: 書名 | F1: 姓名 | G1: 狀態
A2: M00033 | B2: 9789250038261 | C2: 45659 | D2: 45678 | E2: =IF($B2="","",IFERROR(INDEX(書籍!$B$2:$B$2000,MATCH($B2,書籍!$A$2:$A$2000,0)),"（沒建檔）")) -> 漫長的夏天 | F2: =IF($A2="","",IFERROR(INDEX(會員!$B$2:$B$2000,MATCH($A2,會員!$A$2:$A$2000,0)),"（沒建檔）")) -> 王思妤 | G2: =IF($B2="","",IF($D2="","未還","已還")) -> 已還
A3: M00014 | B3: 9789583750502 | C3: 45661 | D3: 45682 | E3: =IF($B3="","",IFERROR(INDEX(書籍!$B$2:$B$2000,MATCH($B3,書籍!$A$2:$A$2000,0)),"（沒建檔）")) -> 看不見的咖啡館 | F3: =IF($A3="","",IFERROR(INDEX(會員!$B$2:$B$2000,MATCH($A3,會員!$A$2:$A$2000,0)),"（沒建檔）")) -> 吳雅婷 | G3: =IF($B3="","",IF($D3="","未還","已還")) -> 已還
A4: M00019 | B4: 9781422930533 | C4: 45661 | D4: 45665 | E4: =IF($B4="","",IFERROR(INDEX(書籍!$B$2:$B$2000,MATCH($B4,書籍!$A$2:$A$2000,0)),"（沒建檔）")) -> 漫長的回信 | F4: =IF($A4="","",IFERROR(INDEX(會員!$B$2:$B$2000,MATCH($A4,會員!$A$2:$A$2000,0)),"（沒建檔）")) -> 曾淑芬 | G4: =IF($B4="","",IF($D4="","未還","已還")) -> 已還
A5: M00023 | B5: 9783842462014 | C5: 45662 | D5: 45688 | E5: =IF($B5="","",IFERROR(INDEX(書籍!$B$2:$B$2000,MATCH($B5,書籍!$A$2:$A$2000,0)),"（沒建檔）")) -> 十二個廚房 | F5: =IF($A5="","",IFERROR(INDEX(會員!$B$2:$B$2000,MATCH($A5,會員!$A$2:$A$2000,0)),"（沒建檔）")) -> 郭妍希 | G5: =IF($B5="","",IF($D5="","未還","已還")) -> 已還
A6: M00017 | B6: 9787563547494 | C6: 45662 | D6: 45679 | E6: =IF($B6="","",IFERROR(INDEX(書籍!$B$2:$B$2000,MATCH($B6,書籍!$A$2:$A$2000,0)),"（沒建檔）")) -> 沉默的鋼琴師 | F6: =IF($A6="","",IFERROR(INDEX(會員!$B$2:$B$2000,MATCH($A6,會員!$A$2:$A$2000,0)),"（沒建檔）")) -> 吳芃穎 | G6: =IF($B6="","",IF($D6="","未還","已還")) -> 已還
A7: M00009 | B7: 9786362213715 | C7: 45663 | D7: 45669 | E7: =IF($B7="","",IFERROR(INDEX(書籍!$B$2:$B$2000,MATCH($B7,書籍!$A$2:$A$2000,0)),"（沒建檔）")) -> 海邊的旅人 | F7: =IF($A7="","",IFERROR(INDEX(會員!$B$2:$B$2000,MATCH($A7,會員!$A$2:$A$2000,0)),"（沒建檔）")) -> 李子涵 | G7: =IF($B7="","",IF($D7="","未還","已還")) -> 已還
A8: M00021 | B8: 9781266632761 | C8: 45663 | D8: 45665 | E8: =IF($B8="","",IFERROR(INDEX(書籍!$B$2:$B$2000,MATCH($B8,書籍!$A$2:$A$2000,0)),"（沒建檔）")) -> 半路上的祕密 | F8: =IF($A8="","",IFERROR(INDEX(會員!$B$2:$B$2000,MATCH($A8,會員!$A$2:$A$2000,0)),"（沒建檔）")) -> 蔡彥廷 | G8: =IF($B8="","",IF($D8="","未還","已還")) -> 已還
A9: M00017 | B9: 9781039781429 | C9: 45664 | D9: 45672 | E9: =IF($B9="","",IFERROR(INDEX(書籍!$B$2:$B$2000,MATCH($B9,書籍!$A$2:$A$2000,0)),"（沒建檔）")) -> 紙上的鋼琴師 | F9: =IF($A9="","",IFERROR(INDEX(會員!$B$2:$B$2000,MATCH($A9,會員!$A$2:$A$2000,0)),"（沒建檔）")) -> 吳芃穎 | G9: =IF($B9="","",IF($D9="","未還","已還")) -> 已還
A10: M00025 | B10: 9782626359199 | C10: 45666 | D10: 45695 | E10: =IF($B10="","",IFERROR(INDEX(書籍!$B$2:$B$2000,MATCH($B10,書籍!$A$2:$A$2000,0)),"（沒建檔）")) -> 小鎮森林 | F10: =IF($A10="","",IFERROR(INDEX(會員!$B$2:$B$2000,MATCH($A10,會員!$A$2:$A$2000,0)),"（沒建檔）")) -> 郭芷萱 | G10: =IF($B10="","",IF($D10="","未還","已還")) -> 已還
A11: M00009 | B11: 9788754426529 | C11: 45666 | D11: 45680 | E11: =IF($B11="","",IFERROR(INDEX(書籍!$B$2:$B$2000,MATCH($B11,書籍!$A$2:$A$2000,0)),"（沒建檔）")) -> 看不見的花園 | F11: =IF($A11="","",IFERROR(INDEX(會員!$B$2:$B$2000,MATCH($A11,會員!$A$2:$A$2000,0)),"（沒建檔）")) -> 李子涵 | G11: =IF($B11="","",IF($D11="","未還","已還")) -> 已還
A12: M00030 | B12: 9787027776118 | C12: 45668 | D12: 45697 | E12: =IF($B12="","",IFERROR(INDEX(書籍!$B$2:$B$2000,MATCH($B12,書籍!$A$2:$A$2000,0)),"（沒建檔）")) -> 轉角夏天 | F12: =IF($A12="","",IFERROR(INDEX(會員!$B$2:$B$2000,MATCH($A12,會員!$A$2:$A$2000,0)),"（沒建檔）")) -> 賴佩珊 | G12: =IF($B12="","",IF($D12="","未還","已還")) -> 已還
A13: M00039 | B13: 9787131573955 | C13: 45668 | D13: 45686 | E13: =IF($B13="","",IFERROR(INDEX(書籍!$B$2:$B$2000,MATCH($B13,書籍!$A$2:$A$2000,0)),"（沒建檔）")) -> 看不見的廚房 | F13: =IF($A13="","",IFERROR(INDEX(會員!$B$2:$B$2000,MATCH($A13,會員!$A$2:$A$2000,0)),"（沒建檔）")) -> 蔡宜庭 | G13: =IF($B13="","",IF($D13="","未還","已還")) -> 已還
... A436: M00011 | B436: 9787027776118 | C436: 45978 | D436: 46006 | E436: =IF($B436="","",IFERROR(INDEX(書籍!$B$2:$B$2000,MATCH($B436,書籍!$A$2:$A$2000,0)),"（沒建檔）")) -> 轉角夏天 | F436: =IF($A436="","",IFERROR(INDEX(會員!$B$2:$B$2000,MATCH($A436,會員!$A$2:$A$2000,0)),"（沒建檔）")) -> 謝子涵 | G436: =IF($B436="","",IF($D436="","未還","已還")) -> 已還
A437: M00026 | B437: 9787001201254 | C437: 45978 | E437: =IF($B437="","",IFERROR(INDEX(書籍!$B$2:$B$2000,MATCH($B437,書籍!$A$2:$A$2000,0)),"（沒建檔）")) -> 月球燈塔 | F437: =IF($A437="","",IFERROR(INDEX(會員!$B$2:$B$2000,MATCH($A437,會員!$A$2:$A$2000,0)),"（沒建檔）")) -> 陳祐誠 | G437: =IF($B437="","",IF($D437="","未還","已還")) -> 未還
A438: M00040 | B438: 9788817790932 | C438: 45978 | D438: 45998 | E438: =IF($B438="","",IFERROR(INDEX(書籍!$B$2:$B$2000,MATCH($B438,書籍!$A$2:$A$2000,0)),"（沒建檔）")) -> 北方信 | F438: =IF($A438="","",IFERROR(INDEX(會員!$B$2:$B$2000,MATCH($A438,會員!$A$2:$A$2000,0)),"（沒建檔）")) -> 吳柏翰 | G438: =IF($B438="","",IF($D438="","未還","已還")) -> 已還
A439: M00008 | B439: 9781361566688 | C439: 45979 | D439: 45986 | E439: =IF($B439="","",IFERROR(INDEX(書籍!$B$2:$B$2000,MATCH($B439,書籍!$A$2:$A$2000,0)),"（沒建檔）")) -> 會說話的貓 | F439: =IF($A439="","",IFERROR(INDEX(會員!$B$2:$B$2000,MATCH($A439,會員!$A$2:$A$2000,0)),"（沒建檔）")) -> 吳彥廷 | G439: =IF($B439="","",IF($D439="","未還","已還")) -> 已還
A440: M00033 | B440: 9788508142675 | C440: 45980 | D440: 45999 | E440: =IF($B440="","",IFERROR(INDEX(書籍!$B$2:$B$2000,MATCH($B440,書籍!$A$2:$A$2000,0)),"（沒建檔）")) -> 深夜的季節 | F440: =IF($A440="","",IFERROR(INDEX(會員!$B$2:$B$2000,MATCH($A440,會員!$A$2:$A$2000,0)),"（沒建檔）")) -> 王思妤 | G440: =IF($B440="","",IF($D440="","未還","已還")) -> 已還
A441: M00018 | B441: 9783638536950 | C441: 45981 | D441: 45999 | E441: =IF($B441="","",IFERROR(INDEX(書籍!$B$2:$B$2000,MATCH($B441,書籍!$A$2:$A$2000,0)),"（沒建檔）")) -> 海邊的季節 | F441: =IF($A441="","",IFERROR(INDEX(會員!$B$2:$B$2000,MATCH($A441,會員!$A$2:$A$2000,0)),"（沒建檔）")) -> 張季軒 | G441: =IF($B441="","",IF($D441="","未還","已還")) -> 已還
A442: M00020 | B442: 9788920199394 | C442: 45982 | E442: =IF($B442="","",IFERROR(INDEX(書籍!$B$2:$B$2000,MATCH($B442,書籍!$A$2:$A$2000,0)),"（沒建檔）")) -> 紙上的手記 | F442: =IF($A442="","",IFERROR(INDEX(會員!$B$2:$B$2000,MATCH($A442,會員!$A$2:$A$2000,0)),"（沒建檔）")) -> 王芷萱 | G442: =IF($B442="","",IF($D442="","未還","已還")) -> 未還
A443: M00002 | B443: 9785454567279 | C443: 45982 | E443: =IF($B443="","",IFERROR(INDEX(書籍!$B$2:$B$2000,MATCH($B443,書籍!$A$2:$A$2000,0)),"（沒建檔）")) -> 會說話的夏天 | F443: =IF($A443="","",IFERROR(INDEX(會員!$B$2:$B$2000,MATCH($A443,會員!$A$2:$A$2000,0)),"（沒建檔）")) -> 洪詠晴 | G443: =IF($B443="","",IF($D443="","未還","已還")) -> 未還
A444: M00037 | B444: 9789730594157 | C444: 45983 | E444: =IF($B444="","",IFERROR(INDEX(書籍!$B$2:$B$2000,MATCH($B444,書籍!$A$2:$A$2000,0)),"（沒建檔）")) -> 半路上的郵差 | F444: =IF($A444="","",IFERROR(INDEX(會員!$B$2:$B$2000,MATCH($A444,會員!$A$2:$A$2000,0)),"（沒建檔）")) -> 郭思妤 | G444: =IF($B444="","",IF($D444="","未還","已還")) -> 未還
A445: M00019 | B445: 9782170876418 | C445: 45983 | D445: 45989 | E445: =IF($B445="","",IFERROR(INDEX(書籍!$B$2:$B$2000,MATCH($B445,書籍!$A$2:$A$2000,0)),"（沒建檔）")) -> 看不見的鐘樓 | F445: =IF($A445="","",IFERROR(INDEX(會員!$B$2:$B$2000,MATCH($A445,會員!$A$2:$A$2000,0)),"（沒建檔）")) -> 曾淑芬 | G445: =IF($B445="","",IF($D445="","未還","已還")) -> 已還
A446: M00037 | B446: 9783842462014 | C446: 45983 | D446: 46005 | E446: =IF($B446="","",IFERROR(INDEX(書籍!$B$2:$B$2000,MATCH($B446,書籍!$A$2:$A$2000,0)),"（沒建檔）")) -> 十二個廚房 | F446: =IF($A446="","",IFERROR(INDEX(會員!$B$2:$B$2000,MATCH($A446,會員!$A$2:$A$2000,0)),"（沒建檔）")) -> 郭思妤 | G446: =IF($B446="","",IF($D446="","未還","已還")) -> 已還
A447: M00002 | B447: 9789987303588 | C447: 45983 | D447: 45999 | E447: =IF($B447="","",IFERROR(INDEX(書籍!$B$2:$B$2000,MATCH($B447,書籍!$A$2:$A$2000,0)),"（沒建檔）")) -> 雨中燈塔 | F447: =IF($A447="","",IFERROR(INDEX(會員!$B$2:$B$2000,MATCH($A447,會員!$A$2:$A$2000,0)),"（沒建檔）")) -> 洪詠晴 | G447: =IF($B447="","",IF($D447="","未還","已還")) -> 已還
A448: M00004 | B448: 9782524309364 | C448: 45984 | D448: 46010 | E448: =IF($B448="","",IFERROR(INDEX(書籍!$B$2:$B$2000,MATCH($B448,書籍!$A$2:$A$2000,0)),"（沒建檔）")) -> 微小的郵差 | F448: =IF($A448="","",IFERROR(INDEX(會員!$B$2:$B$2000,MATCH($A448,會員!$A$2:$A$2000,0)),"（沒建檔）")) -> 郭柏翰 | G448: =IF($B448="","",IF($D448="","未還","已還")) -> 已還
A449: M00011 | B449: 9783703447006 | C449: 45984 | D449: 45994 | E449: =IF($B449="","",IFERROR(INDEX(書籍!$B$2:$B$2000,MATCH($B449,書籍!$A$2:$A$2000,0)),"（沒建檔）")) -> 最後一個偵探 | F449: =IF($A449="","",IFERROR(INDEX(會員!$B$2:$B$2000,MATCH($A449,會員!$A$2:$A$2000,0)),"（沒建檔）")) -> 謝子涵 | G449: =IF($B449="","",IF($D449="","未還","已還")) -> 已還
A450: M00013 | B450: 9787524816980 | C450: 45984 | D450: 45986 | E450: =IF($B450="","",IFERROR(INDEX(書籍!$B$2:$B$2000,MATCH($B450,書籍!$A$2:$A$2000,0)),"（沒建檔）")) -> 深夜的島 | F450: =IF($A450="","",IFERROR(INDEX(會員!$B$2:$B$2000,MATCH($A450,會員!$A$2:$A$2000,0)),"（沒建檔）")) -> 陳祐誠 | G450: =IF($B450="","",IF($D450="","未還","已還")) -> 已還
A451: M00026 | B451: 9785847120432 | C451: 45986 | D451: 46009 | E451: =IF($B451="","",IFERROR(INDEX(書籍!$B$2:$B$2000,MATCH($B451,書籍!$A$2:$A$2000,0)),"（沒建檔）")) -> 漫長的書店 | F451: =IF($A451="","",IFERROR(INDEX(會員!$B$2:$B$2000,MATCH($A451,會員!$A$2:$A$2000,0)),"（沒建檔）")) -> 陳祐誠 | G451: =IF($B451="","",IF($D451="","未還","已還")) -> 已還
A452: M00013 | B452: 9780414474918 | C452: 45986 | D452: 46016 | E452: =IF($B452="","",IFERROR(INDEX(書籍!$B$2:$B$2000,MATCH($B452,書籍!$A$2:$A$2000,0)),"（沒建檔）")) -> 藍色手記 | F452: =IF($A452="","",IFERROR(INDEX(會員!$B$2:$B$2000,MATCH($A452,會員!$A$2:$A$2000,0)),"（沒建檔）")) -> 陳祐誠 | G452: =IF($B452="","",IF($D452="","未還","已還")) -> 已還
A453: M00001 | B453: 9785567735947 | C453: 45987 | D453: 46005 | E453: =IF($B453="","",IFERROR(INDEX(書籍!$B$2:$B$2000,MATCH($B453,書籍!$A$2:$A$2000,0)),"（沒建檔）")) -> 兩個人的偵探 | F453: =IF($A453="","",IFERROR(INDEX(會員!$B$2:$B$2000,MATCH($A453,會員!$A$2:$A$2000,0)),"（沒建檔）")) -> 楊芷萱 | G453: =IF($B453="","",IF($D453="","未還","已還")) -> 已還
A454: M00021 | B454: 9784780777710 | C454: 45988 | E454: =IF($B454="","",IFERROR(INDEX(書籍!$B$2:$B$2000,MATCH($B454,書籍!$A$2:$A$2000,0)),"（沒建檔）")) -> 月球回信 | F454: =IF($A454="","",IFERROR(INDEX(會員!$B$2:$B$2000,MATCH($A454,會員!$A$2:$A$2000,0)),"（沒建檔）")) -> 蔡彥廷 | G454: =IF($B454="","",IF($D454="","未還","已還")) -> 未還
A455: M00026 | B455: 9783909219179 | C455: 45988 | E455: =IF($B455="","",IFERROR(INDEX(書籍!$B$2:$B$2000,MATCH($B455,書籍!$A$2:$A$2000,0)),"（沒建檔）")) -> 海邊的貓 | F455: =IF($A455="","",IFERROR(INDEX(會員!$B$2:$B$2000,MATCH($A455,會員!$A$2:$A$2000,0)),"（沒建檔）")) -> 陳祐誠 | G455: =IF($B455="","",IF($D455="","未還","已還")) -> 未還
A456: M00028 | B456: 9789528573845 | C456: 45988 | D456: 45991 | E456: =IF($B456="","",IFERROR(INDEX(書籍!$B$2:$B$2000,MATCH($B456,書籍!$A$2:$A$2000,0)),"（沒建檔）")) -> 紙上的鋼琴師 | F456: =IF($A456="","",IFERROR(INDEX(會員!$B$2:$B$2000,MATCH($A456,會員!$A$2:$A$2000,0)),"（沒建檔）")) -> 邱沐恩 | G456: =IF($B456="","",IF($D456="","未還","已還")) -> 已還
A457: M00021 | B457: 9787524816980 | C457: 45989 | D457: 46004 | E457: =IF($B457="","",IFERROR(INDEX(書籍!$B$2:$B$2000,MATCH($B457,書籍!$A$2:$A$2000,0)),"（沒建檔）")) -> 深夜的島 | F457: =IF($A457="","",IFERROR(INDEX(會員!$B$2:$B$2000,MATCH($A457,會員!$A$2:$A$2000,0)),"（沒建檔）")) -> 蔡彥廷 | G457: =IF($B457="","",IF($D457="","未還","已還")) -> 已還
A458: M00029 | B458: 9789965256653 | C458: 45990 | E458: =IF($B458="","",IFERROR(INDEX(書籍!$B$2:$B$2000,MATCH($B458,書籍!$A$2:$A$2000,0)),"（沒建檔）")) -> 小鎮河 | F458: =IF($A458="","",IFERROR(INDEX(會員!$B$2:$B$2000,MATCH($A458,會員!$A$2:$A$2000,0)),"（沒建檔）")) -> 賴思妤 | G458: =IF($B458="","",IF($D458="","未還","已還")) -> 未還
A459: M00015 | B459: 9781266632761 | C459: 45990 | D459: 46005 | E459: =IF($B459="","",IFERROR(INDEX(書籍!$B$2:$B$2000,MATCH($B459,書籍!$A$2:$A$2000,0)),"（沒建檔）")) -> 半路上的祕密 | F459: =IF($A459="","",IFERROR(INDEX(會員!$B$2:$B$2000,MATCH($A459,會員!$A$2:$A$2000,0)),"（沒建檔）")) -> 張宜庭 | G459: =IF($B459="","",IF($D459="","未還","已還")) -> 已還
A460: M00026 | B460: 9783267198192 | C460: 45990 | D460: 46005 | E460: =IF($B460="","",IFERROR(INDEX(書籍!$B$2:$B$2000,MATCH($B460,書籍!$A$2:$A$2000,0)),"（沒建檔）")) -> 海邊的廚房 | F460: =IF($A460="","",IFERROR(INDEX(會員!$B$2:$B$2000,MATCH($A460,會員!$A$2:$A$2000,0)),"（沒建檔）")) -> 陳祐誠 | G460: =IF($B460="","",IF($D460="","未還","已還")) -> 已還
A461: M00032 | B461: 9782853749442 | C461: 45991 | D461: 46017 | E461: =IF($B461="","",IFERROR(INDEX(書籍!$B$2:$B$2000,MATCH($B461,書籍!$A$2:$A$2000,0)),"（沒建檔）")) -> 十二個河 | F461: =IF($A461="","",IFERROR(INDEX(會員!$B$2:$B$2000,MATCH($A461,會員!$A$2:$A$2000,0)),"（沒建檔）")) -> 邱承翰 | G461: =IF($B461="","",IF($D461="","未還","已還")) -> 已還
A462: M00022 | B462: 9781003405061 | C462: 45991 | E462: =IF($B462="","",IFERROR(INDEX(書籍!$B$2:$B$2000,MATCH($B462,書籍!$A$2:$A$2000,0)),"（沒建檔）")) -> 藍色咖啡館 | F462: =IF($A462="","",IFERROR(INDEX(會員!$B$2:$B$2000,MATCH($A462,會員!$A$2:$A$2000,0)),"（沒建檔）")) -> 李怡君 | G462: =IF($B462="","",IF($D462="","未還","已還")) -> 未還
...

Sheet 書籍
A1: ISBN | B1: 書名 | C1: 作者 | D1: 未歸還筆數 | E1: 狀態 | F1: 借閱次數 | G1: 排序鍵
A2: 9783504890421 | B2: 遺失的鋼琴師 | C2: 郭雅婷 | D2: =COUNTIFS(借閱!$B$2:$B$2000,$A2,借閱!$D$2:$D$2000,"") -> 0 | E2: =IF(D2>0,"借出中","在店") -> 在店 | F2: =COUNTIF(借閱!$B$2:$B$2000,$A2) -> 4 | G2: =F2+ROW()/100000 -> 4.00002
A3: 9780450426131 | B3: 雨中書店 | C3: 張宜庭 | D3: =COUNTIFS(借閱!$B$2:$B$2000,$A3,借閱!$D$2:$D$2000,"") -> 0 | E3: =IF(D3>0,"借出中","在店") -> 在店 | F3: =COUNTIF(借閱!$B$2:$B$2000,$A3) -> 2 | G3: =F3+ROW()/100000 -> 2.00003
A4: 9781682307557 | B4: 會說話的偵探 | C4: 張家豪 | D4: =COUNTIFS(借閱!$B$2:$B$2000,$A4,借閱!$D$2:$D$2000,"") -> 0 | E4: =IF(D4>0,"借出中","在店") -> 在店 | F4: =COUNTIF(借閱!$B$2:$B$2000,$A4) -> 3 | G4: =F4+ROW()/100000 -> 3.00004
A5: 9781100398464 | B5: 最後一個祕密 | C5: 許妍希 | D5: =COUNTIFS(借閱!$B$2:$B$2000,$A5,借閱!$D$2:$D$2000,"") -> 0 | E5: =IF(D5>0,"借出中","在店") -> 在店 | F5: =COUNTIF(借閱!$B$2:$B$2000,$A5) -> 5 | G5: =F5+ROW()/100000 -> 5.00005
A6: 9788030133486 | B6: 小鎮偵探 | C6: 林沐恩 | D6: =COUNTIFS(借閱!$B$2:$B$2000,$A6,借閱!$D$2:$D$2000,"") -> 0 | E6: =IF(D6>0,"借出中","在店") -> 在店 | F6: =COUNTIF(借閱!$B$2:$B$2000,$A6) -> 6 | G6: =F6+ROW()/100000 -> 6.00006
A7: 9784874298404 | B7: 地下室貓 | C7: 吳建宏 | D7: =COUNTIFS(借閱!$B$2:$B$2000,$A7,借閱!$D$2:$D$2000,"") -> 0 | E7: =IF(D7>0,"借出中","在店") -> 在店 | F7: =COUNTIF(借閱!$B$2:$B$2000,$A7) -> 6 | G7: =F7+ROW()/100000 -> 6.00007
A8: 9787295557518 | B8: 沉默的鐘樓 | C8: 許俊傑 | D8: =COUNTIFS(借閱!$B$2:$B$2000,$A8,借閱!$D$2:$D$2000,"") -> 1 | E8: =IF(D8>0,"借出中","在店") -> 借出中 | F8: =COUNTIF(借閱!$B$2:$B$2000,$A8) -> 5 | G8: =F8+ROW()/100000 -> 5.00008
A9: 9782853749442 | B9: 十二個河 | C9: 張睦晨 | D9: =COUNTIFS(借閱!$B$2:$B$2000,$A9,借閱!$D$2:$D$2000,"") -> 0 | E9: =IF(D9>0,"借出中","在店") -> 在店 | F9: =COUNTIF(借閱!$B$2:$B$2000,$A9) -> 7 | G9: =F9+ROW()/100000 -> 7.00009
A10: 9783638536950 | B10: 海邊的季節 | C10: 王妍希 | D10: =COUNTIFS(借閱!$B$2:$B$2000,$A10,借閱!$D$2:$D$2000,"") -> 1 | E10: =IF(D10>0,"借出中","在店") -> 借出中 | F10: =COUNTIF(借閱!$B$2:$B$2000,$A10) -> 6 | G10: =F10+ROW()/100000 -> 6.0001
A11: 9781332259168 | B11: 深夜的約定 | C11: 謝禹安 | D11: =COUNTIFS(借閱!$B$2:$B$2000,$A11,借閱!$D$2:$D$2000,"") -> 0 | E11: =IF(D11>0,"借出中","在店") -> 在店 | F11: =COUNTIF(借閱!$B$2:$B$2000,$A11) -> 4 | G11: =F11+ROW()/100000 -> 4.00011
A12: 9786362213715 | B12: 海邊的旅人 | C12: 吳建宏 | D12: =COUNTIFS(借閱!$B$2:$B$2000,$A12,借閱!$D$2:$D$2000,"") -> 0 | E12: =IF(D12>0,"借出中","在店") -> 在店 | F12: =COUNTIF(借閱!$B$2:$B$2000,$A12) -> 6 | G12: =F12+ROW()/100000 -> 6.00012
A13: 9788817790932 | B13: 北方信 | C13: 張禹安 | D13: =COUNTIFS(借閱!$B$2:$B$2000,$A13,借閱!$D$2:$D$2000,"") -> 0 | E13: =IF(D13>0,"借出中","在店") -> 在店 | F13: =COUNTIF(借閱!$B$2:$B$2000,$A13) -> 5 | G13: =F13+ROW()/100000 -> 5.00013
... A101: 9787027776118 | B101: 轉角夏天 | C101: 黃家豪 | D101: =COUNTIFS(借閱!$B$2:$B$2000,$A101,借閱!$D$2:$D$2000,"") -> 0 | E101: =IF(D101>0,"借出中","在店") -> 在店 | F101: =COUNTIF(借閱!$B$2:$B$2000,$A101) -> 6 | G101: =F101+ROW()/100000 -> 6.00101

Sheet 會員
A1: 會員編號 | B1: 姓名 | C1: 電話 | D1: 未歸還數
A2: M00001 | B2: 楊芷萱 | C2: 0936-165-072 | D2: =COUNTIFS(借閱!$A$2:$A$2000,$A2,借閱!$D$2:$D$2000,"") -> 3
A3: M00002 | B3: 洪詠晴 | C3: 0910-367-676 | D3: =COUNTIFS(借閱!$A$2:$A$2000,$A3,借閱!$D$2:$D$2000,"") -> 1
A4: M00003 | B4: 曾志明 | C4: 0929-023-911 | D4: =COUNTIFS(借閱!$A$2:$A$2000,$A4,借閱!$D$2:$D$2000,"") -> 1
A5: M00004 | B5: 郭柏翰 | C5: 0917-210-924 | D5: =COUNTIFS(借閱!$A$2:$A$2000,$A5,借閱!$D$2:$D$2000,"") -> 0
A6: M00005 | B6: 賴建宏 | C6: 0917-987-393 | D6: =COUNTIFS(借閱!$A$2:$A$2000,$A6,借閱!$D$2:$D$2000,"") -> 1
A7: M00006 | B7: 廖品妍 | C7: 0955-170-966 | D7: =COUNTIFS(借閱!$A$2:$A$2000,$A7,借閱!$D$2:$D$2000,"") -> 0
A8: M00007 | B8: 郭詠晴 | C8: 0981-142-385 | D8: =COUNTIFS(借閱!$A$2:$A$2000,$A8,借閱!$D$2:$D$2000,"") -> 0
A9: M00008 | B9: 吳彥廷 | C9: 0927-825-558 | D9: =COUNTIFS(借閱!$A$2:$A$2000,$A9,借閱!$D$2:$D$2000,"") -> 0
A10: M00009 | B10: 李子涵 | C10: 0948-360-474 | D10: =COUNTIFS(借閱!$A$2:$A$2000,$A10,借閱!$D$2:$D$2000,"") -> 2
A11: M00010 | B11: 郭柏翰 | C11: 0977-780-468 | D11: =COUNTIFS(借閱!$A$2:$A$2000,$A11,借閱!$D$2:$D$2000,"") -> 1
A12: M00011 | B12: 謝子涵 | C12: 0977-202-111 | D12: =COUNTIFS(借閱!$A$2:$A$2000,$A12,借閱!$D$2:$D$2000,"") -> 0
A13: M00012 | B13: 劉柏翰 | C13: 0937-771-221 | D13: =COUNTIFS(借閱!$A$2:$A$2000,$A13,借閱!$D$2:$D$2000,"") -> 0
... A41: M00040 | B41: 吳柏翰 | C41: 0918-346-351 | D41: =COUNTIFS(借閱!$A$2:$A$2000,$A41,借閱!$D$2:$D$2000,"") -> 0

Sheet 統計
A1: 借閱總筆數 | B1: =COUNTA(借閱!$B$2:$B$2000) -> 501 | D1: 名次 | E1: ISBN | F1: 書名 | G1: 借閱次數
A2: 未歸還筆數 | B2: =COUNTIFS(借閱!$B$2:$B$2000,"<>",借閱!$D$2:$D$2000,"") -> 38 | D2: 1 | E2: =INDEX(書籍!$A$2:$A$101,MATCH(LARGE(書籍!$G$2:$G$101,D2),書籍!$G$2:$G$101,0)) -> 9783516770131 | F2: =INDEX(書籍!$B$2:$B$101,MATCH(LARGE(書籍!$G$2:$G$101,D2),書籍!$G$2:$G$101,0)) -> 深夜的手記 | G2: =INDEX(書籍!$F$2:$F$101,MATCH(LARGE(書籍!$G$2:$G$101,D2),書籍!$G$2:$G$101,0)) -> 9
A3: 借出中的書（本） | B3: =COUNTIF(書籍!$E$2:$E$101,"借出中") -> 37 | D3: 2 | E3: =INDEX(書籍!$A$2:$A$101,MATCH(LARGE(書籍!$G$2:$G$101,D3),書籍!$G$2:$G$101,0)) -> 9787524816980 | F3: =INDEX(書籍!$B$2:$B$101,MATCH(LARGE(書籍!$G$2:$G$101,D3),書籍!$G$2:$G$101,0)) -> 深夜的島 | G3: =INDEX(書籍!$F$2:$F$101,MATCH(LARGE(書籍!$G$2:$G$101,D3),書籍!$G$2:$G$101,0)) -> 8
A4: 重複借出的書（本） | B4: =COUNTIF(書籍!$D$2:$D$101,">1") -> 1 | D4: 3 | E4: =INDEX(書籍!$A$2:$A$101,MATCH(LARGE(書籍!$G$2:$G$101,D4),書籍!$G$2:$G$101,0)) -> 9781679983634 | F4: =INDEX(書籍!$B$2:$B$101,MATCH(LARGE(書籍!$G$2:$G$101,D4),書籍!$G$2:$G$101,0)) -> 最後一個森林 | G4: =INDEX(書籍!$F$2:$F$101,MATCH(LARGE(書籍!$G$2:$G$101,D4),書籍!$G$2:$G$101,0)) -> 8
D5: 4 | E5: =INDEX(書籍!$A$2:$A$101,MATCH(LARGE(書籍!$G$2:$G$101,D5),書籍!$G$2:$G$101,0)) -> 9789955491217 | F5: =INDEX(書籍!$B$2:$B$101,MATCH(LARGE(書籍!$G$2:$G$101,D5),書籍!$G$2:$G$101,0)) -> 轉角鋼琴師 | G5: =INDEX(書籍!$F$2:$F$101,MATCH(LARGE(書籍!$G$2:$G$101,D5),書籍!$G$2:$G$101,0)) -> 7
D6: 5 | E6: =INDEX(書籍!$A$2:$A$101,MATCH(LARGE(書籍!$G$2:$G$101,D6),書籍!$G$2:$G$101,0)) -> 9784071906799 | F6: =INDEX(書籍!$B$2:$B$101,MATCH(LARGE(書籍!$G$2:$G$101,D6),書籍!$G$2:$G$101,0)) -> 深夜的河 | G6: =INDEX(書籍!$F$2:$F$101,MATCH(LARGE(書籍!$G$2:$G$101,D6),書籍!$G$2:$G$101,0)) -> 7
D7: 6 | E7: =INDEX(書籍!$A$2:$A$101,MATCH(LARGE(書籍!$G$2:$G$101,D7),書籍!$G$2:$G$101,0)) -> 9788215834962 | F7: =INDEX(書籍!$B$2:$B$101,MATCH(LARGE(書籍!$G$2:$G$101,D7),書籍!$G$2:$G$101,0)) -> 地下室鋼琴師 | G7: =INDEX(書籍!$F$2:$F$101,MATCH(LARGE(書籍!$G$2:$G$101,D7),書籍!$G$2:$G$101,0)) -> 7
D8: 7 | E8: =INDEX(書籍!$A$2:$A$101,MATCH(LARGE(書籍!$G$2:$G$101,D8),書籍!$G$2:$G$101,0)) -> 9788754426529 | F8: =INDEX(書籍!$B$2:$B$101,MATCH(LARGE(書籍!$G$2:$G$101,D8),書籍!$G$2:$G$101,0)) -> 看不見的花園 | G8: =INDEX(書籍!$F$2:$F$101,MATCH(LARGE(書籍!$G$2:$G$101,D8),書籍!$G$2:$G$101,0)) -> 7
D9: 8 | E9: =INDEX(書籍!$A$2:$A$101,MATCH(LARGE(書籍!$G$2:$G$101,D9),書籍!$G$2:$G$101,0)) -> 9782919809752 | F9: =INDEX(書籍!$B$2:$B$101,MATCH(LARGE(書籍!$G$2:$G$101,D9),書籍!$G$2:$G$101,0)) -> 圖書館地圖 | G9: =INDEX(書籍!$F$2:$F$101,MATCH(LARGE(書籍!$G$2:$G$101,D9),書籍!$G$2:$G$101,0)) -> 7
D10: 9 | E10: =INDEX(書籍!$A$2:$A$101,MATCH(LARGE(書籍!$G$2:$G$101,D10),書籍!$G$2:$G$101,0)) -> 9787563547494 | F10: =INDEX(書籍!$B$2:$B$101,MATCH(LARGE(書籍!$G$2:$G$101,D10),書籍!$G$2:$G$101,0)) -> 沉默的鋼琴師 | G10: =INDEX(書籍!$F$2:$F$101,MATCH(LARGE(書籍!$G$2:$G$101,D10),書籍!$G$2:$G$101,0)) -> 7
D11: 10 | E11: =INDEX(書籍!$A$2:$A$101,MATCH(LARGE(書籍!$G$2:$G$101,D11),書籍!$G$2:$G$101,0)) -> 9789046821947 | F11: =INDEX(書籍!$B$2:$B$101,MATCH(LARGE(書籍!$G$2:$G$101,D11),書籍!$G$2:$G$101,0)) -> 地下室夏天 | G11: =INDEX(書籍!$F$2:$F$101,MATCH(LARGE(書籍!$G$2:$G$101,D11),書籍!$G$2:$G$101,0)) -> 7
